<?xml version="1.0" encoding="utf-8"?>
<!-- This URDF was automatically created by SolidWorks to URDF Exporter! Originally created by Stephen Brawner (brawner@gmail.com) 
     Commit Version: 1.6.0-4-g7f85cfe  Build Version: 1.6.7995.38578
     For more information, please see http://wiki.ros.org/sw_urdf_exporter -->
<robot
  name="Rove">
  <link
    name="Chassis">
    <inertial>
      <origin
        xyz="0.0146284813389947 -1.89563371274376E-06 0.0723541928691957"
        rpy="0 0 0" />
      <mass
        value="3.09641268033491" />
      <inertia
        ixx="0.0419741968772416"
        ixy="-3.7560549183201E-15"
        ixz="-8.03647666606979E-18"
        iyy="0.0615690596509833"
        iyz="4.53243009823761E-13"
        izz="0.10204579421495" />
    </inertial>
    <visual>
      <origin
        xyz="0 0 0"
        rpy="0 0 0" />
      <geometry>
        <mesh
          filename="package://Rove/meshes/Chassis.STL" />
      </geometry>
      <material
        name="">
        <color
          rgba="0.752941176470588 0.752941176470588 0.752941176470588 1" />
      </material>
    </visual>
    <collision>
      <origin
        xyz="0 0 0"
        rpy="0 0 0" />
      <geometry>
        <mesh
          filename="package://Rove/meshes/Chassis.STL" />
      </geometry>
    </collision>
  </link>
  <link
    name="Suspension Right">
    <inertial>
      <origin
        xyz="-0.000284315368573762 0.0394999999999512 -0.0949070775921543"
        rpy="0 0 0" />
      <mass
        value="0.491075869325468" />
      <inertia
        ixx="0.000777748708473674"
        ixy="9.63439205576138E-18"
        ixz="3.02056525137579E-06"
        iyy="0.00221150585237779"
        iyz="-7.8876216877661E-09"
        izz="0.00149474981209495" />
    </inertial>
    <visual>
      <origin
        xyz="0 0 0"
        rpy="0 0 0" />
      <geometry>
        <mesh
          filename="package://Rove/meshes/Suspension Right.STL" />
      </geometry>
      <material
        name="">
        <color
          rgba="0.752941176470588 0.752941176470588 0.752941176470588 1" />
      </material>
    </visual>
    <collision>
      <origin
        xyz="0 0 0"
        rpy="0 0 0" />
      <geometry>
        <mesh
          filename="package://Rove/meshes/Suspension Right.STL" />
      </geometry>
    </collision>
  </link>
  <joint
    name="Revolute"
    type="continuous">
    <origin
      xyz="0.0599999999999999 -0.264999999999999 0.0350000000000001"
      rpy="0 0.0406665076873908 3.14159265358979" />
    <parent
      link="Chassis" />
    <child
      link="Suspension Right" />
    <axis
      xyz="0 1 0" />
  </joint>
  <link
    name="Wheel Base">
    <inertial>
      <origin
        xyz="-0.232338622821477 -0.156715594710097 -0.325252654063905"
        rpy="0 0 0" />
      <mass
        value="1.59064873828344" />
      <inertia
        ixx="0.00332993948905121"
        ixy="-1.37696076565265E-06"
        ixz="-5.37296524247919E-06"
        iyy="0.00326373133283035"
        iyz="-3.07688885292126E-06"
        izz="0.00325480760241221" />
    </inertial>
    <visual>
      <origin
        xyz="0 0 0"
        rpy="0 0 0" />
      <geometry>
        <mesh
          filename="package://Rove/meshes/Wheel Base.STL" />
      </geometry>
      <material
        name="">
        <color
          rgba="0.752941176470588 0.752941176470588 0.752941176470588 1" />
      </material>
    </visual>
    <collision>
      <origin
        xyz="0 0 0"
        rpy="0 0 0" />
      <geometry>
        <mesh
          filename="package://Rove/meshes/Wheel Base.STL" />
      </geometry>
    </collision>
  </link>
  <joint
    name="Rigid"
    type="fixed">
    <origin
      xyz="-0.270420585894539 -0.0150007511058859 -0.0413359060619553"
      rpy="-0.0119323064051078 0 -1.5707963267949" />
    <parent
      link="Suspension Right" />
    <child
      link="Wheel Base" />
    <axis
      xyz="0 0 0" />
  </joint>
  <link
    name="Wheel1">
    <inertial>
      <origin
        xyz="0.0636406878077729 0.166120083271174 -0.303455350484078"
        rpy="0 0 0" />
      <mass
        value="1.06266656397985" />
      <inertia
        ixx="0.00867837868482245"
        ixy="-9.75781955236954E-19"
        ixz="-1.50131373611095E-17"
        iyy="0.00867837868482245"
        iyz="4.13921841052304E-17"
        izz="0.011118515627338" />
    </inertial>
    <visual>
      <origin
        xyz="0 0 0"
        rpy="0 0 0" />
      <geometry>
        <mesh
          filename="package://Rove/meshes/Wheel1.STL" />
      </geometry>
      <material
        name="">
        <color
          rgba="0.752941176470588 0.752941176470588 0.752941176470588 1" />
      </material>
    </visual>
    <collision>
      <origin
        xyz="0 0 0"
        rpy="0 0 0" />
      <geometry>
        <mesh
          filename="package://Rove/meshes/Wheel1.STL" />
      </geometry>
    </collision>
  </link>
  <joint
    name="Rotate1"
    type="fixed">
    <origin
      xyz="-0.552456102886383 -0.206911372789634 -0.154790132380014"
      rpy="-1.57079632679499 0.0801270394491507 1.5707963267949" />
    <parent
      link="Wheel Base" />
    <child
      link="Wheel1" />
    <axis
      xyz="-0.132336510163755 -0.991204846677859 0" />
  </joint>
  <link
    name="Wheel Base 2">
    <inertial>
      <origin
        xyz="-0.232338624163035 -0.156715594834493 -0.325252653955168"
        rpy="0 0 0" />
      <mass
        value="1.59064872533312" />
      <inertia
        ixx="0.00332993948466885"
        ixy="-1.3769601811676E-06"
        ixz="-5.37296595460627E-06"
        iyy="0.00326373132752293"
        iyz="-3.07689071031699E-06"
        izz="0.00325480760010007" />
    </inertial>
    <visual>
      <origin
        xyz="0 0 0"
        rpy="0 0 0" />
      <geometry>
        <mesh
          filename="package://Rove/meshes/Wheel Base 2.STL" />
      </geometry>
      <material
        name="">
        <color
          rgba="0.752941176470588 0.752941176470588 0.752941176470588 1" />
      </material>
    </visual>
    <collision>
      <origin
        xyz="0 0 0"
        rpy="0 0 0" />
      <geometry>
        <mesh
          filename="package://Rove/meshes/Wheel Base 2.STL" />
      </geometry>
    </collision>
  </link>
  <joint
    name="Fixed 1"
    type="fixed">
    <origin
      xyz="0.407514224595884 -0.015000751105886 -0.00812327219102477"
      rpy="0.503078806236402 0 -1.5707963267949" />
    <parent
      link="Suspension Right" />
    <child
      link="Wheel Base 2" />
    <axis
      xyz="0 0 0" />
  </joint>
  <link
    name="Wheel2">
    <inertial>
      <origin
        xyz="0.0636406878077646 0.166120083271187 -0.303455350484077"
        rpy="0 0 0" />
      <mass
        value="1.06266656397985" />
      <inertia
        ixx="0.00867837868482245"
        ixy="1.04083408558608E-17"
        ixz="6.00469807216239E-17"
        iyy="0.00867837868482245"
        iyz="-1.92467887650303E-17"
        izz="0.011118515627338" />
    </inertial>
    <visual>
      <origin
        xyz="0 0 0"
        rpy="0 0 0" />
      <geometry>
        <mesh
          filename="package://Rove/meshes/Wheel2.STL" />
      </geometry>
      <material
        name="">
        <color
          rgba="0.752941176470588 0.752941176470588 0.752941176470588 1" />
      </material>
    </visual>
    <collision>
      <origin
        xyz="0 0 0"
        rpy="0 0 0" />
      <geometry>
        <mesh
          filename="package://Rove/meshes/Wheel2.STL" />
      </geometry>
    </collision>
  </link>
  <joint
    name="Rotatey"
    type="fixed">
    <origin
      xyz="-0.552456102886372 -0.0340272945561178 -0.196708084429408"
      rpy="-1.57079632679493 1.12732459064575 1.57079632679489" />
    <parent
      link="Wheel Base 2" />
    <child
      link="Wheel2" />
    <axis
      xyz="0 0 0" />
  </joint>
  <link
    name="Differential connector">
    <inertial>
      <origin
        xyz="0.202421857244755 -0.380825083152069 0.0563336914023347"
        rpy="0 0 0" />
      <mass
        value="0.0149887953807079" />
      <inertia
        ixx="1.69088722417064E-05"
        ixy="1.52566240950461E-07"
        ixz="-3.77254799777031E-13"
        iyy="1.86393645388861E-05"
        iyz="3.30076701014792E-14"
        izz="1.79715804057173E-06" />
    </inertial>
    <visual>
      <origin
        xyz="0 0 0"
        rpy="0 0 0" />
      <geometry>
        <mesh
          filename="package://Rove/meshes/Differential connector.STL" />
      </geometry>
      <material
        name="">
        <color
          rgba="0.752941176470588 0.752941176470588 0.752941176470588 1" />
      </material>
    </visual>
    <collision>
      <origin
        xyz="0 0 0"
        rpy="0 0 0" />
      <geometry>
        <mesh
          filename="package://Rove/meshes/Differential connector.STL" />
      </geometry>
    </collision>
  </link>
  <joint
    name="Fixed"
    type="fixed">
    <origin
      xyz="-0.234842675299956 0.390733701419906 -0.0942441749076858"
      rpy="0 0 0.0872664625997107" />
    <parent
      link="Suspension Right" />
    <child
      link="Differential connector" />
    <axis
      xyz="0 0 0" />
  </joint>
  <link
    name="Tie rod ball2">
    <inertial>
      <origin
        xyz="1.60982338570648E-15 6.38378239159465E-16 -0.00497493718553338"
        rpy="0 0 0" />
      <mass
        value="0.000742388240421719" />
      <inertia
        ixx="2.74446280084428E-08"
        ixy="3.30872245021211E-24"
        ixz="-2.5890804943719E-24"
        iyy="2.74446280084427E-08"
        iyz="-2.81337602417678E-24"
        izz="4.60438954975872E-08" />
    </inertial>
    <visual>
      <origin
        xyz="0 0 0"
        rpy="0 0 0" />
      <geometry>
        <mesh
          filename="package://Rove/meshes/Tie rod ball2.STL" />
      </geometry>
      <material
        name="">
        <color
          rgba="0.96078431372549 0.96078431372549 0.964705882352941 1" />
      </material>
    </visual>
    <collision>
      <origin
        xyz="0 0 0"
        rpy="0 0 0" />
      <geometry>
        <mesh
          filename="package://Rove/meshes/Tie rod ball2.STL" />
      </geometry>
    </collision>
  </link>
  <joint
    name="Fixed3"
    type="continuous">
    <origin
      xyz="0.202247547109796 -0.382817472666401 -0.000755825091999413"
      rpy="-1.57079632679472 -0.356589409874478 -0.0872664625997732" />
    <parent
      link="Differential connector" />
    <child
      link="Tie rod ball2" />
    <axis
      xyz="0 0 1" />
  </joint>
  <link
    name="Tie rod">
    <inertial>
      <origin
        xyz="0.0104421747737389 0.0607861228068002 -0.00231988781136289"
        rpy="0 0 0" />
      <mass
        value="0.0233826113190036" />
      <inertia
        ixx="5.81287678407495E-06"
        ixy="-2.70664313172421E-12"
        ixz="4.44672241760014E-12"
        iyy="1.04660838334745E-06"
        iyz="2.77528475170752E-12"
        izz="5.81289092676996E-06" />
    </inertial>
    <visual>
      <origin
        xyz="0 0 0"
        rpy="0 0 0" />
      <geometry>
        <mesh
          filename="package://Rove/meshes/Tie rod.STL" />
      </geometry>
      <material
        name="">
        <color
          rgba="0.752941176470588 0.752941176470588 0.752941176470588 1" />
      </material>
    </visual>
    <collision>
      <origin
        xyz="0 0 0"
        rpy="0 0 0" />
      <geometry>
        <mesh
          filename="package://Rove/meshes/Tie rod.STL" />
      </geometry>
    </collision>
  </link>
  <joint
    name="Rotate2"
    type="revolute">
    <origin
      xyz="0 0.00999999999999998 0"
      rpy="0.00565546888988213 0.263273418509483 -1.24497576442754" />
    <parent
      link="Tie rod ball2" />
    <child
      link="Tie rod" />
    <axis
      xyz="0 1 0" />
    <limit
      lower="-0.52207"
      upper="0.26333"
      effort="0"
      velocity="0" />
  </joint>
  <link
    name="Tie rod ball1">
    <inertial>
      <origin
        xyz="4.9960036108132E-16 -3.33066907387547E-16 -0.00497493718553667"
        rpy="0 0 0" />
      <mass
        value="0.000742388240421719" />
      <inertia
        ixx="2.74446280084428E-08"
        ixy="3.30872245021213E-24"
        ixz="1.63495802368174E-23"
        iyy="2.74446280084428E-08"
        iyz="-2.96574787758966E-24"
        izz="4.60438954975872E-08" />
    </inertial>
    <visual>
      <origin
        xyz="0 0 0"
        rpy="0 0 0" />
      <geometry>
        <mesh
          filename="package://Rove/meshes/Tie rod ball1.STL" />
      </geometry>
      <material
        name="">
        <color
          rgba="0.96078431372549 0.96078431372549 0.964705882352941 1" />
      </material>
    </visual>
    <collision>
      <origin
        xyz="0 0 0"
        rpy="0 0 0" />
      <geometry>
        <mesh
          filename="package://Rove/meshes/Tie rod ball1.STL" />
      </geometry>
    </collision>
  </link>
  <joint
    name="Rotate3"
    type="revolute">
    <origin
      xyz="0.00563885347695928 0.124827882835183 -0.00361475433768826"
      rpy="1.85270510601966 -0.360765726608758 -1.68140280038764" />
    <parent
      link="Tie rod" />
    <child
      link="Tie rod ball1" />
    <axis
      xyz="0 0 1" />
    <limit
      lower="-0.52194"
      upper="0.26346"
      effort="0"
      velocity="0" />
  </joint>
  <link
    name="Differential1">
    <inertial>
      <origin
        xyz="0.0276859032835543 -0.083769766449292 -0.000734660301647824"
        rpy="0 0 0" />
      <mass
        value="0.335764973483015" />
      <inertia
        ixx="0.00299183211553723"
        ixy="-0.000248367189200687"
        ixz="6.09589312354869E-09"
        iyy="0.000174473767449322"
        iyz="1.27913517023785E-09"
        izz="0.0031586013155375" />
    </inertial>
    <visual>
      <origin
        xyz="0 0 0"
        rpy="0 0 0" />
      <geometry>
        <mesh
          filename="package://Rove/meshes/Differential1.STL" />
      </geometry>
      <material
        name="">
        <color
          rgba="0.752941176470588 0.752941176470588 0.752941176470588 1" />
      </material>
    </visual>
    <collision>
      <origin
        xyz="0 0 0"
        rpy="0 0 0" />
      <geometry>
        <mesh
          filename="package://Rove/meshes/Differential1.STL" />
      </geometry>
    </collision>
  </link>
  <joint
    name="Rotate 4"
    type="fixed">
    <origin
      xyz="-0.0443994688086841 -0.204836866255469 -0.00573076227753548"
      rpy="-3.14159265358979 0 2.67349178569295" />
    <parent
      link="Tie rod ball1" />
    <child
      link="Differential1" />
    <axis
      xyz="0 0 0" />
  </joint>
  <link
    name="Suspension Left">
    <inertial>
      <origin
        xyz="-0.000284315368573207 -0.0395000000000141 -0.0949070775921687"
        rpy="0 0 0" />
      <mass
        value="0.491075869325463" />
      <inertia
        ixx="0.000777748708473673"
        ixy="-6.52867234237413E-18"
        ixz="3.02056525141191E-06"
        iyy="0.00221150585237778"
        iyz="-7.88762156746879E-09"
        izz="0.00149474981209495" />
    </inertial>
    <visual>
      <origin
        xyz="0 0 0"
        rpy="0 0 0" />
      <geometry>
        <mesh
          filename="package://Rove/meshes/Suspension Left.STL" />
      </geometry>
      <material
        name="">
        <color
          rgba="0.752941176470588 0.752941176470588 0.752941176470588 1" />
      </material>
    </visual>
    <collision>
      <origin
        xyz="0 0 0"
        rpy="0 0 0" />
      <geometry>
        <mesh
          filename="package://Rove/meshes/Suspension Left.STL" />
      </geometry>
    </collision>
  </link>
  <joint
    name="rotate6"
    type="continuous">
    <origin
      xyz="0.0600000000000007 0.264999999999956 0.0350000000000008"
      rpy="0 -0.0249598836537905 3.14159265358979" />
    <parent
      link="Chassis" />
    <child
      link="Suspension Left" />
    <axis
      xyz="0 1 0" />
  </joint>
  <link
    name="Wheel base3">
    <inertial>
      <origin
        xyz="-0.23233862415525 -0.156715594837322 -0.325252653954173"
        rpy="0 0 0" />
      <mass
        value="1.59064872540484" />
      <inertia
        ixx="0.00332993948464931"
        ixy="-1.37696016745237E-06"
        ixz="-5.3729659580356E-06"
        iyy="0.0032637313275381"
        iyz="-3.07689073136537E-06"
        izz="0.00325480760010247" />
    </inertial>
    <visual>
      <origin
        xyz="0 0 0"
        rpy="0 0 0" />
      <geometry>
        <mesh
          filename="package://Rove/meshes/Wheel base3.STL" />
      </geometry>
      <material
        name="">
        <color
          rgba="0.752941176470588 0.752941176470588 0.752941176470588 1" />
      </material>
    </visual>
    <collision>
      <origin
        xyz="0 0 0"
        rpy="0 0 0" />
      <geometry>
        <mesh
          filename="package://Rove/meshes/Wheel base3.STL" />
      </geometry>
    </collision>
  </link>
  <joint
    name="fixedf"
    type="fixed">
    <origin
      xyz="-0.408397164852578 0.0150007511058267 -0.0043651931557472"
      rpy="0.511666469193183 0 1.5707963267949" />
    <parent
      link="Suspension Left" />
    <child
      link="Wheel base3" />
    <axis
      xyz="0 0 0" />
  </joint>
  <link
    name="Wheel3">
    <inertial>
      <origin
        xyz="0.0636406878077499 0.166120083271174 -0.303455350484088"
        rpy="0 0 0" />
      <mass
        value="1.06266656397985" />
      <inertia
        ixx="0.00867837868482245"
        ixy="-4.55364912443912E-18"
        ixz="1.84958914822195E-16"
        iyy="0.00867837868482244"
        iyz="1.01069859315838E-16"
        izz="0.011118515627338" />
    </inertial>
    <visual>
      <origin
        xyz="0 0 0"
        rpy="0 0 0" />
      <geometry>
        <mesh
          filename="package://Rove/meshes/Wheel3.STL" />
      </geometry>
      <material
        name="">
        <color
          rgba="0.752941176470588 0.752941176470588 0.752941176470588 1" />
      </material>
    </visual>
    <collision>
      <origin
        xyz="0 0 0"
        rpy="0 0 0" />
      <geometry>
        <mesh
          filename="package://Rove/meshes/Wheel3.STL" />
      </geometry>
    </collision>
  </link>
  <joint
    name="revolute2"
    type="fixed">
    <origin
      xyz="-0.552456102886265 -0.106631317255014 -0.496152091749674"
      rpy="1.5707963267952 -0.0801270394491497 -1.5707963267949" />
    <parent
      link="Wheel base3" />
    <child
      link="Wheel3" />
    <axis
      xyz="0 0 0" />
  </joint>
  <link
    name="Wheel base4">
    <inertial>
      <origin
        xyz="-0.232338624266259 -0.156715594777223 -0.325252653977031"
        rpy="0 0 0" />
      <mass
        value="1.59064872438714" />
      <inertia
        ixx="0.00332993948494114"
        ixy="-1.37696049733446E-06"
        ixz="-5.3729658709659E-06"
        iyy="0.00326373132737462"
        iyz="-3.0768902869957E-06"
        izz="0.00325480759995235" />
    </inertial>
    <visual>
      <origin
        xyz="0 0 0"
        rpy="0 0 0" />
      <geometry>
        <mesh
          filename="package://Rove/meshes/Wheel base4.STL" />
      </geometry>
      <material
        name="">
        <color
          rgba="0.752941176470588 0.752941176470588 0.752941176470588 1" />
      </material>
    </visual>
    <collision>
      <origin
        xyz="0 0 0"
        rpy="0 0 0" />
      <geometry>
        <mesh
          filename="package://Rove/meshes/Wheel base4.STL" />
      </geometry>
    </collision>
  </link>
  <joint
    name="Fixedg"
    type="fixed">
    <origin
      xyz="0.270193358064833 0.0150007511058332 -0.0436572254982473"
      rpy="-0.00334464344833156 0 1.5707963267949" />
    <parent
      link="Suspension Left" />
    <child
      link="Wheel base4" />
    <axis
      xyz="0 0 0" />
  </joint>
  <link
    name="Wheel4">
    <inertial>
      <origin
        xyz="0.0636406878077865 0.166120083271183 -0.303455350484075"
        rpy="0 0 0" />
      <mass
        value="1.06266656397985" />
      <inertia
        ixx="0.00867837868482248"
        ixy="-3.08997619158369E-18"
        ixz="-1.17961653326017E-16"
        iyy="0.00867837868482246"
        iyz="3.73941249376366E-17"
        izz="0.0111185156273381" />
    </inertial>
    <visual>
      <origin
        xyz="0 0 0"
        rpy="0 0 0" />
      <geometry>
        <mesh
          filename="package://Rove/meshes/Wheel4.STL" />
      </geometry>
      <material
        name="">
        <color
          rgba="0.752941176470588 0.752941176470588 0.752941176470588 1" />
      </material>
    </visual>
    <collision>
      <origin
        xyz="0 0 0"
        rpy="0 0 0" />
      <geometry>
        <mesh
          filename="package://Rove/meshes/Wheel4.STL" />
      </geometry>
    </collision>
  </link>
  <joint
    name="Revolutet"
    type="fixed">
    <origin
      xyz="0.0544545980817925 -0.113325688191729 -0.152964607511344"
      rpy="-1.57079632679461 0.119135000779939 -1.5707963267949" />
    <parent
      link="Wheel base4" />
    <child
      link="Wheel4" />
    <axis
      xyz="0 0 0" />
  </joint>
  <link
    name="Connector">
    <inertial>
      <origin
        xyz="0.202421855624515 -0.380825083010316 0.0563336908961466"
        rpy="0 0 0" />
      <mass
        value="0.014988791920935" />
      <inertia
        ixx="1.69088723559561E-05"
        ixy="1.52566227213728E-07"
        ixz="-2.62405704341002E-13"
        iyy="1.86393644973262E-05"
        iyz="2.29596754946867E-14"
        izz="1.79715787682291E-06" />
    </inertial>
    <visual>
      <origin
        xyz="0 0 0"
        rpy="0 0 0" />
      <geometry>
        <mesh
          filename="package://Rove/meshes/Connector.STL" />
      </geometry>
      <material
        name="">
        <color
          rgba="0.752941176470588 0.752941176470588 0.752941176470588 1" />
      </material>
    </visual>
    <collision>
      <origin
        xyz="0 0 0"
        rpy="0 0 0" />
      <geometry>
        <mesh
          filename="package://Rove/meshes/Connector.STL" />
      </geometry>
    </collision>
  </link>
  <joint
    name="fixedc"
    type="fixed">
    <origin
      xyz="-0.234842675299956 0.332733701419863 -0.0942441749076274"
      rpy="0 0 0.0872664625997097" />
    <parent
      link="Suspension Left" />
    <child
      link="Connector" />
    <axis
      xyz="0 0 0" />
  </joint>
  <link
    name="Tie ball3">
    <inertial>
      <origin
        xyz="3.33066907387547E-16 -6.93889390390723E-16 -0.0049749371855331"
        rpy="0 0 0" />
      <mass
        value="0.000742388240421719" />
      <inertia
        ixx="2.74446280084428E-08"
        ixy="1.65436122510606E-24"
        ixz="3.46603084297972E-23"
        iyy="2.74446280084427E-08"
        iyz="2.56351037772471E-23"
        izz="4.60438954975871E-08" />
    </inertial>
    <visual>
      <origin
        xyz="0 0 0"
        rpy="0 0 0" />
      <geometry>
        <mesh
          filename="package://Rove/meshes/Tie ball3.STL" />
      </geometry>
      <material
        name="">
        <color
          rgba="0.96078431372549 0.96078431372549 0.964705882352941 1" />
      </material>
    </visual>
    <collision>
      <origin
        xyz="0 0 0"
        rpy="0 0 0" />
      <geometry>
        <mesh
          filename="package://Rove/meshes/Tie ball3.STL" />
      </geometry>
    </collision>
  </link>
  <joint
    name="fixedv"
    type="continuous">
    <origin
      xyz="0.202247547109796 -0.382817472666402 -0.000755825091999427"
      rpy="-1.5707963267949 -0.290963018550302 -0.0872664625997097" />
    <parent
      link="Connector" />
    <child
      link="Tie ball3" />
    <axis
      xyz="0 0 1" />
  </joint>
  <link
    name="Tie rod3">
    <inertial>
      <origin
        xyz="0.0102741452285572 0.0603146868677285 -0.00236869209927884"
        rpy="0 0 0" />
      <mass
        value="0.0233825643204007" />
      <inertia
        ixx="5.81288283906259E-06"
        ixy="-4.7240154734891E-13"
        ixz="2.13001177820228E-12"
        iyy="1.04660621641098E-06"
        iyz="-9.81423765502388E-13"
        izz="5.81288226252135E-06" />
    </inertial>
    <visual>
      <origin
        xyz="0 0 0"
        rpy="0 0 0" />
      <geometry>
        <mesh
          filename="package://Rove/meshes/Tie rod3.STL" />
      </geometry>
      <material
        name="">
        <color
          rgba="0.752941176470588 0.752941176470588 0.752941176470588 1" />
      </material>
    </visual>
    <collision>
      <origin
        xyz="0 0 0"
        rpy="0 0 0" />
      <geometry>
        <mesh
          filename="package://Rove/meshes/Tie rod3.STL" />
      </geometry>
    </collision>
  </link>
  <joint
    name="Rotatea"
    type="revolute">
    <origin
      xyz="0 0.01 0"
      rpy="0.107226472437579 0.225269093052848 -1.2227474064692" />
    <parent
      link="Tie ball3" />
    <child
      link="Tie rod3" />
    <axis
      xyz="0 1 0" />
    <limit
      lower="-0.5363"
      upper="0.2491"
      effort="0"
      velocity="0" />
  </joint>
  <link
    name="Tie ball 2">
    <inertial>
      <origin
        xyz="1.22124532708767E-15 1.11022302462516E-16 -0.00497493718553329"
        rpy="0 0 0" />
      <mass
        value="0.000742388240421719" />
      <inertia
        ixx="2.74446280084428E-08"
        ixy="-2.48154183761869E-24"
        ixz="-5.16443462157297E-22"
        iyy="2.74446280084428E-08"
        iyz="3.00092699813362E-24"
        izz="4.60438954975872E-08" />
    </inertial>
    <visual>
      <origin
        xyz="0 0 0"
        rpy="0 0 0" />
      <geometry>
        <mesh
          filename="package://Rove/meshes/Tie ball 2.STL" />
      </geometry>
      <material
        name="">
        <color
          rgba="0.96078431372549 0.96078431372549 0.964705882352941 1" />
      </material>
    </visual>
    <collision>
      <origin
        xyz="0 0 0"
        rpy="0 0 0" />
      <geometry>
        <mesh
          filename="package://Rove/meshes/Tie ball 2.STL" />
      </geometry>
    </collision>
  </link>
  <joint
    name="Rotate78"
    type="revolute">
    <origin
      xyz="0.0054273959593613 0.12435470583135 -0.00349007855042224"
      rpy="1.93651505405689 -0.888854864798664 -1.86803022100149" />
    <parent
      link="Tie rod3" />
    <child
      link="Tie ball 2" />
    <axis
      xyz="0 0 1" />
    <limit
      lower="-0.55789"
      upper="0.22751"
      effort="0"
      velocity="0" />
  </joint>
  <link
    name="Differential 2">
    <inertial>
      <origin
        xyz="0.0276859032835554 -0.0937697664492874 -0.000734660301648011"
        rpy="0 0 0" />
      <mass
        value="0.335764973483015" />
      <inertia
        ixx="0.00299183211553723"
        ixy="-0.000248367189200687"
        ixz="6.09589312354848E-09"
        iyy="0.000174473767449322"
        iyz="1.27913517023873E-09"
        izz="0.0031586013155375" />
    </inertial>
    <visual>
      <origin
        xyz="0 0 0"
        rpy="0 0 0" />
      <geometry>
        <mesh
          filename="package://Rove/meshes/Differential 2.STL" />
      </geometry>
      <material
        name="">
        <color
          rgba="0.752941176470588 0.752941176470588 0.752941176470588 1" />
      </material>
    </visual>
    <collision>
      <origin
        xyz="0 0 0"
        rpy="0 0 0" />
      <geometry>
        <mesh
          filename="package://Rove/meshes/Differential 2.STL" />
      </geometry>
    </collision>
  </link>
  <joint
    name="Rotater"
    type="fixed">
    <origin
      xyz="0.303348138777784 0.229448960572226 -0.00573076227756035"
      rpy="3.1415926535897 0 2.22514352720603" />
    <parent
      link="Tie ball 2" />
    <child
      link="Differential 2" />
    <axis
      xyz="0 0 0" />
  </joint>
  <link
    name="Differential">
    <inertial>
      <origin
        xyz="8.93064728280102E-07 -1.45650556514221E-06 0.00485080864835977"
        rpy="0 0 0" />
      <mass
        value="0.335764973483015" />
      <inertia
        ixx="0.00299183211553723"
        ixy="-0.000248367189200687"
        ixz="6.0958931235485E-09"
        iyy="0.000174473767449322"
        iyz="1.27913517023872E-09"
        izz="0.0031586013155375" />
    </inertial>
    <visual>
      <origin
        xyz="0 0 0"
        rpy="0 0 0" />
      <geometry>
        <mesh
          filename="package://Rove/meshes/Differential.STL" />
      </geometry>
      <material
        name="">
        <color
          rgba="0.752941176470588 0.752941176470588 0.752941176470588 1" />
      </material>
    </visual>
    <collision>
      <origin
        xyz="0 0 0"
        rpy="0 0 0" />
      <geometry>
        <mesh
          filename="package://Rove/meshes/Differential.STL" />
      </geometry>
    </collision>
  </link>
  <joint
    name="Duff"
    type="continuous">
    <origin
      xyz="-0.0669 -3.63360839802304E-05 -0.0658295810435418"
      rpy="0 0 -3.04457084601802" />
    <parent
      link="Chassis" />
    <child
      link="Differential" />
    <axis
      xyz="0 0 1" />
  </joint>
</robot>